Workbook

Sheet Find & Replace
A1: # | B1: Page | C1: URL path | D1: Find (current text) | E1: Replace with / action | F1: Type | G1: Priority | H1: Status | I1: Notes
A2: 1 | B2: All pages | C2: - | D2: budtender(s) | E2: associate(s) or staff | F2: Wording | G2: High | H2: To do | I2: Search every page, template and image alt text.
A3: 2 | B3: All pages | C3: - | D3: dispensary / dispensaries (not partner names) | E3: store(s) | F3: Wording | G3: High | H3: To do | I3: Leave third-party company names untouched.
A4: 3 | B4: All pages | C4: - | D4: Metrc / METRC / BioTrack | E4: state tracking and reporting integrations | F4: Wording | G4: High | H4: To do | I4: On Compliance, Inventory and Integrations pages, rewrite the section instead of swapping words.
A5: 4 | B5: All pages | C5: - | D5: seed-to-sale | E5: full traceability | F5: Wording | G5: High | H5: To do
A6: 5 | B6: All pages | C6: - | D6: "gram" / "every gram" | E6: "item" / "every item" | F6: Wording | G6: Medium | H6: To do
A7: 6 | B7: All pages | C7: - | D7: any remaining "cannabis" | E7: "regulated retail" (or delete) | F7: Wording | G7: High | H7: To do | I7: Check meta tags, alt text, blog titles, form labels and testimonials.
A8: 7 | B8: All pages | C8: - | D8: Grammar left by earlier word swaps: 'worked in retailers', 'run a any', 'Elevate Your retail shop Operations', 'for retailers' in titles | E8: Fix wording and capitalization | F8: Typo | G8: Medium | H8: To do | I8: See the page rows for exact strings.
A9: 8 | B9: All pages | C9: - | D9: Nav and footer link "State Laws: Cannabis regulations by state" | E9: Remove, or move to a separate resource site | F9: Decision | G9: High | H9: To do | I9: See State Laws page.
A10: 9 | B10: All pages | C10: - | D10: Top nav "Product" link | E10: Point to a real page (e.g. /grow/point-of-sale) or build a Product overview page | F10: Technical | G10: High | H10: To do | I10: Currently returns a 404.
A11: 10 | B11: All pages | C11: - | D11: Every page title is "Bleaum" | E11: Unique title per page, e.g. "Point of Sale | Bleaum" | F11: Technical | G11: High | H11: To do | I11: Also fixes Blog pages that only add "- Bleaum".
A12: 11 | B12: All pages | C12: - | D12: Every meta description is "Empowering businesses with innovative solutions for growth and success." | E12: Unique description per page. Home: "Bleaum is your business in a box: POS, invoicing, inventory, ordering, delivery and AI on one real-time platform." | F12: Technical | G12: High | H12: To do
A13: 12 | B13: All pages | C13: - | D13: Share image points to your-website-url.com (placeholder) | E13: Host a real 1152x648 image and update og:image and twitter:image | F13: Technical | G13: High | H13: To do | I13: Links shared on social show no preview today.
A14: 13 | B14: All pages | C14: - | D14: Footer "© 2025 Bleaum" | E14: "© 2026 Bleaum" (or a dynamic year) | F14: Wording | G14: Low | H14: To do
A15: 14 | B15: All pages | C15: - | D15: Footer tagline "Empowering businesses with innovative solutions for growth and success." | E15: "Your business in a box." or similar | F15: Wording | G15: Medium | H15: To do
A16: 15 | B16: All pages | C16: - | D16: Named customer testimonials on many pages (Perry Jones, AJ, Collin, Hugo, Cam, Casey, Abigail, Will, Samantha, Diana, Andrew H., Dominique) | E16: Get written permission; consider anonymizing business names | F16: Verify | G16: High | H16: To do | I16: Business names such as Happy Root and Project Releaf can themselves point to the industry.
A17: 16 | B17: All pages | C17: - | D17: Company counts: 300+ (site), "Hundreds of retailers", 200+ (NVIDIA deck) | E17: Use one documented number everywhere, including every grant and program application | F17: Verify | G17: High | H17: To do
A18: 17 | B18: All pages | C18: - | D18: Absolute claims: 99.9% uptime, 99.9% compliance, 100% compliant, 100% secure, "No more fines" | E18: Remove, or replace with measured and documentable statements | F18: Verify | G18: High | H18: To do | I18: Absolutes create liability if a customer is ever fined or breached.
A19: 18 | B19: All pages | C19: - | D19: Old pages and posts | E19: Add 301 redirects when URLs change | F19: Technical | G19: Medium | H19: To do | I19: Search engines and archives keep old versions; redirects keep links working but do not erase history.
A20: 19 | B20: Home | C20: / | D20: Hero: "Where Retail Runs Smart / Trusted by 300+ retailers and specialty retailers" | E20: New hero, e.g. "Run your whole business from one hand." plus the 'business in a box' subline | F20: Decision | G20: Medium | H20: To do | I20: Introduce handheld, invoicing and AI once they are live.
A21: 20 | B21: Home | C21: / | D21: Inventory demo: Blue Dream, OG Kush Pre-rolls, Sativa Gummies, CBD Tincture | E21: Neutral items, e.g. Canvas Tote, Ceramic Mug, Leather Wallet (low stock), Candle Set | F21: Wording | G21: High | H21: To do | I21: Keep the low-stock warning on one item.
A22: 21 | B22: Home | C22: / | D22: Delivery demo uses customer names as drivers (AJ, Perry, Andrew) | E22: Placeholder driver names | F22: Wording | G22: Low | H22: To do
A23: 22 | B23: Home | C23: / | D23: Compliance Ready card: "Metrc integration" | E23: "State reporting integrations" | F23: Wording | G23: High | H23: To do
A24: 23 | B24: Home | C24: / | D24: "Metrc, BioTrack & state compliance systems" | E24: "State tracking and reporting integrations" | F24: Wording | G24: High | H24: To do
A25: 24 | B25: Home | C25: / | D25: Industries: Cannabis Retail & Delivery / Pharmacies & Wellness / High-Compliance Retail | E25: Retail & Specialty Stores / Wholesale & Distribution / Regulated Markets | F25: Wording | G25: High | H25: To do | I25: Update card text to match.
A26: 25 | B26: Home | C26: / | D26: Stats: 300+ retailers, 98% satisfaction, 99.9% uptime, 50% time saved, 24/7 support | E26: Keep only what you can document | F26: Verify | G26: High | H26: To do
A27: 26 | B27: Home | C27: / | D27: "SOC 2 compliant" | E27: Keep only if you hold a current SOC 2 report; otherwise remove or say "in progress" | F27: Verify | G27: High | H27: To do
A28: 27 | B28: Home | C28: / | D28: "Our Professional Expertise ... gallery of successful projects" | E28: "Explore the platform" (reads like an agency, not a product) | F28: Wording | G28: Low | H28: To do
A29: 28 | B29: Home | C29: / | D29: "POS onboard in 24 hours", "Transparent pricing, no hidden fees" | E29: Verify, or soften | F29: Verify | G29: Medium | H29: To do
A30: 29 | B30: Home | C30: / | D30: "Environmental impact reduction" (Receipts) | E30: Remove unless substantiated | F30: Verify | G30: Low | H30: To do
A31: 30 | B31: Home | C31: / | D31: Customer quotes (AJ/Happy Root, Collin/Park Social, Hugo/Go Green, Cam/Project Releaf, Perry Jones) | E31: Permission and wording check; "delivery times improved by 40%" needs support | F31: Verify | G31: High | H31: To do
A32: 31 | B32: Point of Sale | C32: /grow/point-of-sale | D32: "whether you run a any high-stakes retail" | E32: "whether you run any high-stakes retail operation" | F32: Typo | G32: Medium | H32: To do
A33: 32 | B33: Point of Sale | C33: /grow/point-of-sale | D33: "Automatic METRC sync" / "METRC and BioTrack sync" | E33: "Automatic state reporting sync" | F33: Wording | G33: High | H33: To do
A34: 33 | B34: Point of Sale | C34: /grow/point-of-sale | D34: "Your budtenders will thank you" / "New budtenders are confident on day one" | E34: "Your team will thank you" / "New staff are confident on day one" | F34: Wording | G34: High | H34: To do
A35: 34 | B35: Point of Sale | C35: /grow/point-of-sale | D35: "Our support team has actually worked in retailers" | E35: "worked in retail" | F35: Typo | G35: Medium | H35: To do
A36: 35 | B36: Point of Sale | C36: /grow/point-of-sale | D36: "Compliance anxiety / Audit-ready, always" row | E36: Keep concept; reword without brand names | F36: Wording | G36: Medium | H36: To do
A37: 36 | B37: Point of Sale | C37: /grow/point-of-sale | D37: 30-second checkout, 3x faster, 99.9% compliance, 90% faster training, 25% higher sales | E37: Verify or remove | F37: Verify | G37: High | H37: To do | I37: Includes the "Numbers That Matter" block.
A38: 37 | B38: Point of Sale | C38: /grow/point-of-sale | D38: "Passed our state audit with zero issues. The inspector was impressed." | E38: Neutralize or remove; confirm permission | F38: Verify | G38: Medium | H38: To do
A39: 38 | B39: Point of Sale | C39: /grow/point-of-sale | D39: "24/7 Human Support ... No bots" | E39: Confirm staffing truly covers 24/7 | F39: Verify | G39: Medium | H39: To do
A40: 39 | B40: Point of Sale | C40: /grow/point-of-sale | D40: Integration chips: METRC Sync | E40: "State Reporting Sync" | F40: Wording | G40: High | H40: To do
...

Sheet Summary
A1: Website update summary
A3: By type | B3: Total | C3: To do | D3: In progress | E3: Done | F3: Skipped
A4: Wording | B4: =COUNTIF('Find & Replace'!$F$2:$F$130,A4) -> 49 | C4: =COUNTIFS('Find & Replace'!$F$2:$F$130,$A4,'Find & Replace'!$H$2:$H$130,"To do") -> 49 | D4: =COUNTIFS('Find & Replace'!$F$2:$F$130,$A4,'Find & Replace'!$H$2:$H$130,"In progress") -> 0 | E4: =COUNTIFS('Find & Replace'!$F$2:$F$130,$A4,'Find & Replace'!$H$2:$H$130,"Done") -> 0 | F4: =COUNTIFS('Find & Replace'!$F$2:$F$130,$A4,'Find & Replace'!$H$2:$H$130,"Skipped") -> 0
A5: Typo | B5: =COUNTIF('Find & Replace'!$F$2:$F$130,A5) -> 8 | C5: =COUNTIFS('Find & Replace'!$F$2:$F$130,$A5,'Find & Replace'!$H$2:$H$130,"To do") -> 8 | D5: =COUNTIFS('Find & Replace'!$F$2:$F$130,$A5,'Find & Replace'!$H$2:$H$130,"In progress") -> 0 | E5: =COUNTIFS('Find & Replace'!$F$2:$F$130,$A5,'Find & Replace'!$H$2:$H$130,"Done") -> 0 | F5: =COUNTIFS('Find & Replace'!$F$2:$F$130,$A5,'Find & Replace'!$H$2:$H$130,"Skipped") -> 0
A6: Decision | B6: =COUNTIF('Find & Replace'!$F$2:$F$130,A6) -> 13 | C6: =COUNTIFS('Find & Replace'!$F$2:$F$130,$A6,'Find & Replace'!$H$2:$H$130,"To do") -> 13 | D6: =COUNTIFS('Find & Replace'!$F$2:$F$130,$A6,'Find & Replace'!$H$2:$H$130,"In progress") -> 0 | E6: =COUNTIFS('Find & Replace'!$F$2:$F$130,$A6,'Find & Replace'!$H$2:$H$130,"Done") -> 0 | F6: =COUNTIFS('Find & Replace'!$F$2:$F$130,$A6,'Find & Replace'!$H$2:$H$130,"Skipped") -> 0
A7: Verify | B7: =COUNTIF('Find & Replace'!$F$2:$F$130,A7) -> 37 | C7: =COUNTIFS('Find & Replace'!$F$2:$F$130,$A7,'Find & Replace'!$H$2:$H$130,"To do") -> 37 | D7: =COUNTIFS('Find & Replace'!$F$2:$F$130,$A7,'Find & Replace'!$H$2:$H$130,"In progress") -> 0 | E7: =COUNTIFS('Find & Replace'!$F$2:$F$130,$A7,'Find & Replace'!$H$2:$H$130,"Done") -> 0 | F7: =COUNTIFS('Find & Replace'!$F$2:$F$130,$A7,'Find & Replace'!$H$2:$H$130,"Skipped") -> 0
A8: Legal review | B8: =COUNTIF('Find & Replace'!$F$2:$F$130,A8) -> 7 | C8: =COUNTIFS('Find & Replace'!$F$2:$F$130,$A8,'Find & Replace'!$H$2:$H$130,"To do") -> 7 | D8: =COUNTIFS('Find & Replace'!$F$2:$F$130,$A8,'Find & Replace'!$H$2:$H$130,"In progress") -> 0 | E8: =COUNTIFS('Find & Replace'!$F$2:$F$130,$A8,'Find & Replace'!$H$2:$H$130,"Done") -> 0 | F8: =COUNTIFS('Find & Replace'!$F$2:$F$130,$A8,'Find & Replace'!$H$2:$H$130,"Skipped") -> 0
A9: Keep | B9: =COUNTIF('Find & Replace'!$F$2:$F$130,A9) -> 3 | C9: =COUNTIFS('Find & Replace'!$F$2:$F$130,$A9,'Find & Replace'!$H$2:$H$130,"To do") -> 3 | D9: =COUNTIFS('Find & Replace'!$F$2:$F$130,$A9,'Find & Replace'!$H$2:$H$130,"In progress") -> 0 | E9: =COUNTIFS('Find & Replace'!$F$2:$F$130,$A9,'Find & Replace'!$H$2:$H$130,"Done") -> 0 | F9: =COUNTIFS('Find & Replace'!$F$2:$F$130,$A9,'Find & Replace'!$H$2:$H$130,"Skipped") -> 0
A10: Technical | B10: =COUNTIF('Find & Replace'!$F$2:$F$130,A10) -> 12 | C10: =COUNTIFS('Find & Replace'!$F$2:$F$130,$A10,'Find & Replace'!$H$2:$H$130,"To do") -> 12 | D10: =COUNTIFS('Find & Replace'!$F$2:$F$130,$A10,'Find & Replace'!$H$2:$H$130,"In progress") -> 0 | E10: =COUNTIFS('Find & Replace'!$F$2:$F$130,$A10,'Find & Replace'!$H$2:$H$130,"Done") -> 0 | F10: =COUNTIFS('Find & Replace'!$F$2:$F$130,$A10,'Find & Replace'!$H$2:$H$130,"Skipped") -> 0
A11: Total | B11: =SUM(B4:B10) -> 129 | C11: =SUM(C4:C10) -> 129 | D11: =SUM(D4:D10) -> 0 | E11: =SUM(E4:E10) -> 0 | F11: =SUM(F4:F10) -> 0
A13: By priority | B13: Total | C13: To do | D13: In progress | E13: Done | F13: Skipped
A14: High | B14: =COUNTIF('Find & Replace'!$G$2:$G$130,A14) -> 63 | C14: =COUNTIFS('Find & Replace'!$G$2:$G$130,$A14,'Find & Replace'!$H$2:$H$130,"To do") -> 63 | D14: =COUNTIFS('Find & Replace'!$G$2:$G$130,$A14,'Find & Replace'!$H$2:$H$130,"In progress") -> 0 | E14: =COUNTIFS('Find & Replace'!$G$2:$G$130,$A14,'Find & Replace'!$H$2:$H$130,"Done") -> 0 | F14: =COUNTIFS('Find & Replace'!$G$2:$G$130,$A14,'Find & Replace'!$H$2:$H$130,"Skipped") -> 0
A15: Medium | B15: =COUNTIF('Find & Replace'!$G$2:$G$130,A15) -> 38 | C15: =COUNTIFS('Find & Replace'!$G$2:$G$130,$A15,'Find & Replace'!$H$2:$H$130,"To do") -> 38 | D15: =COUNTIFS('Find & Replace'!$G$2:$G$130,$A15,'Find & Replace'!$H$2:$H$130,"In progress") -> 0 | E15: =COUNTIFS('Find & Replace'!$G$2:$G$130,$A15,'Find & Replace'!$H$2:$H$130,"Done") -> 0 | F15: =COUNTIFS('Find & Replace'!$G$2:$G$130,$A15,'Find & Replace'!$H$2:$H$130,"Skipped") -> 0
A16: Low | B16: =COUNTIF('Find & Replace'!$G$2:$G$130,A16) -> 28 | C16: =COUNTIFS('Find & Replace'!$G$2:$G$130,$A16,'Find & Replace'!$H$2:$H$130,"To do") -> 28 | D16: =COUNTIFS('Find & Replace'!$G$2:$G$130,$A16,'Find & Replace'!$H$2:$H$130,"In progress") -> 0 | E16: =COUNTIFS('Find & Replace'!$G$2:$G$130,$A16,'Find & Replace'!$H$2:$H$130,"Done") -> 0 | F16: =COUNTIFS('Find & Replace'!$G$2:$G$130,$A16,'Find & Replace'!$H$2:$H$130,"Skipped") -> 0
A18: Counts update automatically from the Type, Priority and Status columns on the Find & Replace tab.

Sheet Not yet reviewed
A1: Page / area | B1: Why it still needs review
A2: /resources (Resources hub) | B2: Not fetched.
A3: /company (Company hub) | B3: Not fetched.
A4: /contact | B4: Linked from Integrations page; confirm it exists.
A5: /terms, /privacy, /cookies | B5: Legal pages: have counsel review any wording changes, including references to industries served and data handling.
A6: Blog posts: /blog/bleaum-delivery-solution, /bleaum-ecommerce-mobile, /bleaum-inventory-management, /bleaum-pay, /bleaum-pos-system | B6: Only the blog index was read; the post bodies need review.
A7: SOP guides: /resources/sops/all, /resources/sops/checklists and each guide | B7: Only the hub was read.
A8: Images and video (hero, screenshots, demo video, logos) | B8: Check for cannabis products, packaging, signage and brand names in screenshots and alt text.
A9: App store listings, Google Play listing, social profiles, Crunchbase and press | B9: Outside the website, but they describe the same company; keep them consistent.

Sheet Legend
A1: How to use | B1: Work down the Find & Replace tab. Filter by Page, Type or Priority and set Status as you go.
A2: Wording | B2: Straight text swap.
A3: Typo | B3: Spelling, grammar or capitalization fix.
A4: Decision | B4: Needs a business choice before changing.
A5: Verify | B5: A number, claim or permission that must be backed by records before it stays on the site.
A6: Legal review | B6: Have counsel, a payments attorney or your processor review before changing or promoting.
A7: Keep | B7: No change needed.
A8: Technical | B8: Developer fix: titles, meta tags, links, redirects, forms.
A9: Priority | B9: High = visible cannabis wording, risky claims, or broken pages. Medium = consistency and accuracy. Low = polish.
A10: Source | B10: Live pages read in this conversation on bleaum.io: Home, Point of Sale, Ecommerce, Marketing, Payments, Delivery, Reporting, Compliance, Inventory, Integrations, Industries, About, Support, Careers, Demo, Refer, State Laws, SOPs and Blog index. /product returned a 404.
